Traceback (most recent call last):
  File "/opt/hostedtoolcache/Python/3.8.10/x64/lib/python3.8/site-packages/jupyter_cache/executors/utils.py", line 51, in single_nb_execution
    executenb(
  File "/opt/hostedtoolcache/Python/3.8.10/x64/lib/python3.8/site-packages/nbclient/client.py", line 1112, in execute
    return NotebookClient(nb=nb, resources=resources, km=km, **kwargs).execute()
  File "/opt/hostedtoolcache/Python/3.8.10/x64/lib/python3.8/site-packages/nbclient/util.py", line 74, in wrapped
    return just_run(coro(*args, **kwargs))
  File "/opt/hostedtoolcache/Python/3.8.10/x64/lib/python3.8/site-packages/nbclient/util.py", line 53, in just_run
    return loop.run_until_complete(coro)
  File "/opt/hostedtoolcache/Python/3.8.10/x64/lib/python3.8/asyncio/base_events.py", line 616, in run_until_complete
    return future.result()
  File "/opt/hostedtoolcache/Python/3.8.10/x64/lib/python3.8/site-packages/nbclient/client.py", line 553, in async_execute
    await self.async_execute_cell(
  File "/opt/hostedtoolcache/Python/3.8.10/x64/lib/python3.8/site-packages/nbclient/client.py", line 857, in async_execute_cell
    self._check_raise_for_error(cell, exec_reply)
  File "/opt/hostedtoolcache/Python/3.8.10/x64/lib/python3.8/site-packages/nbclient/client.py", line 760, in _check_raise_for_error
    raise CellExecutionError.from_cell_and_msg(cell, exec_reply_content)
nbclient.exceptions.CellExecutionError: An error occurred while executing the following cell:
------------------
gene = Seq( "GTGAAAAAGATGCAATCTATCGTACTCGCACTTTCCCTGGTTCTGGTCGCTCCCATGGCA"
            "GCACAGGCTGCGGAAATTACGTTAGTCCCGTCACTAAAATTACAGATAGGCGATCGTGAT"
            "AATCGTGGCTATTACTGGGATGGAGGTCACTGGCGCGACCACGGCTGGTGGAAACAACAT"
            "TATGAATGGCGAGGCAGTCGCTGGCACCTACACGGACCGCCGCCACCGCCCGCCACCAT"
            "AAGAAAGCTCCTCATGATCATCACGGCGGTCATGGTCCAGGCAAACATCACCGCTAA")
gene.translate(table="Bacterial", cds = True)
------------------

[0;31m---------------------------------------------------------------------------[0m
[0;31mTranslationError[0m                          Traceback (most recent call last)
[0;32m<ipython-input-31-fda024f2884f>[0m in [0;36m<module>[0;34m[0m
[1;32m      4[0m             [0;34m"TATGAATGGCGAGGCAGTCGCTGGCACCTACACGGACCGCCGCCACCGCCCGCCACCAT"[0m[0;34m[0m[0;34m[0m[0m
[1;32m      5[0m             "AAGAAAGCTCCTCATGATCATCACGGCGGTCATGGTCCAGGCAAACATCACCGCTAA")
[0;32m----> 6[0;31m [0mgene[0m[0;34m.[0m[0mtranslate[0m[0;34m([0m[0mtable[0m[0;34m=[0m[0;34m"Bacterial"[0m[0;34m,[0m [0mcds[0m [0;34m=[0m [0;32mTrue[0m[0;34m)[0m[0;34m[0m[0;34m[0m[0m
[0m
[0;32m/opt/hostedtoolcache/Python/3.8.10/x64/lib/python3.8/site-packages/Bio/Seq.py[0m in [0;36mtranslate[0;34m(self, table, stop_symbol, to_stop, cds, gap)[0m
[1;32m   1020[0m [0;34m[0m[0m
[1;32m   1021[0m         return Seq(
[0;32m-> 1022[0;31m             [0m_translate_str[0m[0;34m([0m[0mstr[0m[0;34m([0m[0mself[0m[0;34m)[0m[0;34m,[0m [0mcodon_table[0m[0;34m,[0m [0mstop_symbol[0m[0;34m,[0m [0mto_stop[0m[0;34m,[0m [0mcds[0m[0;34m,[0m [0mgap[0m[0;34m=[0m[0mgap[0m[0;34m)[0m[0;34m[0m[0;34m[0m[0m
[0m[1;32m   1023[0m         )
[1;32m   1024[0m [0;34m[0m[0m

[0;32m/opt/hostedtoolcache/Python/3.8.10/x64/lib/python3.8/site-packages/Bio/Seq.py[0m in [0;36m_translate_str[0;34m(sequence, table, stop_symbol, to_stop, cds, pos_stop, gap)[0m
[1;32m   2320[0m             )
[1;32m   2321[0m         [0;32mif[0m [0mn[0m [0;34m%[0m [0;36m3[0m [0;34m!=[0m [0;36m0[0m[0;34m:[0m[0;34m[0m[0;34m[0m[0m
[0;32m-> 2322[0;31m             raise CodonTable.TranslationError(
[0m[1;32m   2323[0m                 [0;34mf"Sequence length {n} is not a multiple of three"[0m[0;34m[0m[0;34m[0m[0m
[1;32m   2324[0m             )

[0;31mTranslationError[0m: Sequence length 296 is not a multiple of three
TranslationError: Sequence length 296 is not a multiple of three

